<?xml version="1.0" ?>
<!-- =================================================================================== -->
<!-- |    This document was autogenerated by xacro from dual_arms.urdf.xacro           | -->
<!-- |    EDITING THIS FILE BY HAND IS NOT RECOMMENDED                                 | -->
<!-- =================================================================================== -->
<robot name="dual_arms">
  <!-- Conversion were obtained from http://www.e-paint.co.uk/Lab_values.asp
       unless otherwise stated. -->
  <!-- World -->
  <link name="world"/>
  <joint name="ar4_base_joint" type="fixed">
    <origin rpy="0 0 -1.57" xyz="0 0 0"/>
    <parent link="world"/>
    <child link="ar4_base_link"/>
  </joint>
  <link name="ar4_base_link">
    <inertial>
      <origin rpy="0 0 0" xyz="-4.6941E-06 0.054174 0.038824"/>
      <mass value="0.7102"/>
      <inertia ixx="0.0039943" ixy="3.697E-07" ixz="-5.7364E-08" iyy="0.0014946" iyz="-0.00036051" izz="0.0042554"/>
    </inertial>
    <visual>
      <origin rpy="0 0 0" xyz="0 0 0"/>
      <geometry>
        <mesh filename="file:///home/omar-magdy/gp_ws/install/annin_ar4_description/share/annin_ar4_description/meshes/ar4_mk3/base_link.STL"/>
      </geometry>
      <material name="">
        <color rgba="1 1 0 1"/>
      </material>
    </visual>
    <collision>
      <origin rpy="0 0 0" xyz="0 0 0"/>
      <geometry>
        <mesh filename="file:///home/omar-magdy/gp_ws/install/annin_ar4_description/share/annin_ar4_description/meshes/ar4_mk3/base_link.STL"/>
      </geometry>
    </collision>
  </link>
  <link name="ar4_link_1">
    <inertial>
      <origin rpy="0 0 0" xyz="-0.022706 0.04294 -0.12205"/>
      <mass value="0.88065"/>
      <inertia ixx="0.0034" ixy="0.00042296" ixz="-0.00089231" iyy="0.0041778" iyz="0.0010848" izz="0.0027077"/>
    </inertial>
    <visual>
      <origin rpy="0 0 0" xyz="0 0 0"/>
      <geometry>
        <mesh filename="file:///home/omar-magdy/gp_ws/install/annin_ar4_description/share/annin_ar4_description/meshes/ar4_mk3/link_1.STL"/>
      </geometry>
      <material name="">
        <color rgba="1 1 0 1"/>
      </material>
    </visual>
    <collision>
      <origin rpy="0 0 0" xyz="0 0 0"/>
      <geometry>
        <mesh filename="file:///home/omar-magdy/gp_ws/install/annin_ar4_description/share/annin_ar4_description/meshes/ar4_mk3/link_1.STL"/>
      </geometry>
    </collision>
  </link>
  <joint name="ar4_joint_1" type="revolute">
    <origin rpy="3.141592653589793 0 0" xyz="0 0 0"/>
    <parent link="ar4_base_link"/>
    <child link="ar4_link_1"/>
    <axis xyz="0 0 1"/>
    <limit effort="-1" lower="-2.9670597283903604" upper="2.9670597283903604" velocity="1.0472"/>
  </joint>
  <link name="ar4_link_2">
    <inertial>
      <origin rpy="0 0 0" xyz="0.064818 -0.11189 -0.038671"/>
      <mass value="0.57738"/>
      <inertia ixx="0.0047312" ixy="0.0022624" ixz="0.00032144" iyy="0.0020836" iyz="-0.00056569" izz="0.0056129"/>
    </inertial>
    <visual>
      <origin rpy="0 0 0" xyz="0 0 0"/>
      <geometry>
        <mesh filename="file:///home/omar-magdy/gp_ws/install/annin_ar4_description/share/annin_ar4_description/meshes/ar4_mk3/link_2.STL"/>
      </geometry>
      <material name="">
        <color rgba="1 1 0 1"/>
      </material>
    </visual>
    <collision>
      <origin rpy="0 0 0" xyz="0 0 0"/>
      <geometry>
        <mesh filename="file:///home/omar-magdy/gp_ws/install/annin_ar4_description/share/annin_ar4_description/meshes/ar4_mk3/link_2.STL"/>
      </geometry>
    </collision>
  </link>
  <joint name="ar4_joint_2" type="revolute">
    <origin rpy="1.5708 0 -1.5708" xyz="0 0.0642 -0.16977"/>
    <parent link="ar4_link_1"/>
    <child link="ar4_link_2"/>
    <axis xyz="0 0 -1"/>
    <limit effort="-1" lower="-0.7330382858376184" upper="1.5707963267948966" velocity="1.0472"/>
  </joint>
  <link name="ar4_link_3">
    <inertial>
      <origin rpy="0 0 0" xyz="-0.00029765 -0.023661 -0.0019125"/>
      <mass value="0.1787"/>
      <inertia ixx="0.0001685" ixy="-2.7713E-05" ixz="5.6885E-06" iyy="0.00012865" iyz="2.9256E-05" izz="0.00020744"/>
    </inertial>
    <visual>
      <origin rpy="0 0 0" xyz="0 0 0"/>
      <geometry>
        <mesh filename="file:///home/omar-magdy/gp_ws/install/annin_ar4_description/share/annin_ar4_description/meshes/ar4_mk3/link_3.STL"/>
      </geometry>
      <material name="">
        <color rgba="1 1 0 1"/>
      </material>
    </visual>
    <collision>
      <origin rpy="0 0 0" xyz="0 0 0"/>
      <geometry>
        <mesh filename="file:///home/omar-magdy/gp_ws/install/annin_ar4_description/share/annin_ar4_description/meshes/ar4_mk3/link_3.STL"/>
      </geometry>
    </collision>
  </link>
  <joint name="ar4_joint_3" type="revolute">
    <origin rpy="0 0 3.1416" xyz="0 -0.305 0.007"/>
    <parent link="ar4_link_2"/>
    <child link="ar4_link_3"/>
    <axis xyz="0 0 -1"/>
    <limit effort="-1" lower="-1.5533430342749532" upper="0.9075712110370514" velocity="1.0472"/>
  </joint>
  <link name="ar4_link_4">
    <inertial>
      <origin rpy="0 0 0" xyz="-0.0016798 -0.00057319 -0.074404"/>
      <mass value="0.34936"/>
      <inertia ixx="0.0030532" ixy="-1.8615E-05" ixz="-7.0047E-05" iyy="0.0031033" iyz="-2.3301E-05" izz="0.00022264"/>
    </inertial>
    <visual>
      <origin rpy="0 0 0" xyz="0 0 0"/>
      <geometry>
        <mesh filename="file:///home/omar-magdy/gp_ws/install/annin_ar4_description/share/annin_ar4_description/meshes/ar4_mk3/link_4.STL"/>
      </geometry>
      <material name="">
        <color rgba="1 1 0 1"/>
      </material>
    </visual>
    <collision>
      <origin rpy="0 0 0" xyz="0 0 0"/>
      <geometry>
        <mesh filename="file:///home/omar-magdy/gp_ws/install/annin_ar4_description/share/annin_ar4_description/meshes/ar4_mk3/link_4.STL"/>
      </geometry>
    </collision>
  </link>
  <joint name="ar4_joint_4" type="revolute">
    <origin rpy="1.5708 0 -1.5708" xyz="0 0 0.0"/>
    <parent link="ar4_link_3"/>
    <child link="ar4_link_4"/>
    <axis xyz="0 0 -1"/>
    <limit effort="-1" lower="-3.141592653589793" upper="3.141592653589793" velocity="1.0472"/>
  </joint>
  <link name="ar4_link_5">
    <inertial>
      <origin rpy="0 0 0" xyz="0.0015066 -1.3102E-05 -0.012585"/>
      <mass value="0.11562"/>
      <inertia ixx="5.5035E-05" ixy="-1.019E-08" ixz="-2.6243E-06" iyy="8.2921E-05" iyz="1.4437E-08" izz="5.2518E-05"/>
    </inertial>
    <visual>
      <origin rpy="0 0 0" xyz="0 0 0"/>
      <geometry>
        <mesh filename="file:///home/omar-magdy/gp_ws/install/annin_ar4_description/share/annin_ar4_description/meshes/ar4_mk3/link_5.STL"/>
      </geometry>
      <material name="">
        <color rgba="1 1 0 1"/>
      </material>
    </visual>
    <collision>
      <origin rpy="0 0 0" xyz="0 0 0"/>
      <geometry>
        <mesh filename="file:///home/omar-magdy/gp_ws/install/annin_ar4_description/share/annin_ar4_description/meshes/ar4_mk3/link_5.STL"/>
      </geometry>
    </collision>
  </link>
  <joint name="ar4_joint_5" type="revolute">
    <origin rpy="3.141592653589793 0 -1.5708" xyz="0 0 -0.22263"/>
    <parent link="ar4_link_4"/>
    <child link="ar4_link_5"/>
    <axis xyz="1 0 0"/>
    <limit effort="-1" lower="-1.8325957145940461" upper="1.8325957145940461" velocity="1.0472"/>
  </joint>
  <link name="ar4_link_6">
    <inertial>
      <origin rpy="0 0 0" xyz="2.9287E-10 -1.6472E-09 0.0091432"/>
      <mass value="0.013863"/>
      <inertia ixx="1.3596E-06" ixy="3.0585E-13" ixz="5.7102E-14" iyy="1.7157E-06" iyz="6.3369E-09" izz="2.4332E-06"/>
    </inertial>
    <visual>
      <origin rpy="0 0 0" xyz="0 0 0"/>
      <geometry>
        <mesh filename="file:///home/omar-magdy/gp_ws/install/annin_ar4_description/share/annin_ar4_description/meshes/ar4_mk3/link_6.STL"/>
      </geometry>
      <material name="">
        <color rgba="1 1 0 1"/>
      </material>
    </visual>
    <collision>
      <origin rpy="0 0 0" xyz="0 0 0"/>
      <geometry>
        <mesh filename="file:///home/omar-magdy/gp_ws/install/annin_ar4_description/share/annin_ar4_description/meshes/ar4_mk3/link_6.STL"/>
      </geometry>
    </collision>
  </link>
  <joint name="ar4_joint_6" type="revolute">
    <origin rpy="0 0 3.1416" xyz="0.000 0 0.041"/>
    <parent link="ar4_link_5"/>
    <child link="ar4_link_6"/>
    <axis xyz="0 0 1"/>
    <limit effort="-1" lower="-3.141592653589793" upper="3.141592653589793" velocity="1.0472"/>
  </joint>
  <!-- center of the end effector mounting surface on link_6 -->
  <link name="ar4_ee_link"/>
  <joint name="ar4_ee_joint" type="fixed">
    <parent link="ar4_link_6"/>
    <child link="ar4_ee_link"/>
    <origin rpy="0 0 0" xyz="0 0 0.0"/>
  </joint>
  <joint name="ar4_gripper_base_joint" type="fixed">
    <origin rpy="-1.5708 0.0 0.0" xyz="0.0 0.0 0.0"/>
    <parent link="ar4_ee_link"/>
    <child link="ar4_gripper_base_link"/>
  </joint>
  <link name="ar4_gripper_base_link">
    <visual>
      <geometry>
        <mesh filename="file:///home/omar-magdy/gp_ws/install/annin_ar4_description/share/annin_ar4_description/meshes/ar4_gripper/gripper_base_link.stl"/>
      </geometry>
      <material name="">
        <color rgba="1 1 0 1"/>
      </material>
    </visual>
    <collision>
      <geometry>
        <mesh filename="file:///home/omar-magdy/gp_ws/install/annin_ar4_description/share/annin_ar4_description/meshes/ar4_gripper/gripper_base_link.stl"/>
      </geometry>
    </collision>
    <inertial>
      <origin xyz="-0.00073621 -0.02341392 -0.00435302"/>
      <mass value="0.08"/>
      <inertia ixx="0.00002375" ixy="0.00000002" ixz="-0.00000017" iyy="0.00004082" iyz="-0.00000029" izz="0.00004254"/>
    </inertial>
  </link>
  <link name="ar4_gripper_jaw1_link">
    <visual>
      <geometry>
        <mesh filename="file:///home/omar-magdy/gp_ws/install/annin_ar4_description/share/annin_ar4_description/meshes/ar4_gripper/gripper_jaw1_link.stl"/>
      </geometry>
      <material name="">
        <color rgba="1 1 0 1"/>
      </material>
    </visual>
    <collision>
      <geometry>
        <mesh filename="file:///home/omar-magdy/gp_ws/install/annin_ar4_description/share/annin_ar4_description/meshes/ar4_gripper/gripper_jaw1_link.stl"/>
      </geometry>
    </collision>
    <inertial>
      <origin xyz="-0.00435839 -0.00469536 0.00757141"/>
      <mass value="0.01"/>
      <inertia ixx="0.00000123" ixy="-0.00000004" ixz="0.00000012" iyy="0.00000115" iyz="0.00000016" izz="0.00000102"/>
    </inertial>
  </link>
  <link name="ar4_gripper_jaw2_link">
    <visual>
      <geometry>
        <mesh filename="file:///home/omar-magdy/gp_ws/install/annin_ar4_description/share/annin_ar4_description/meshes/ar4_gripper/gripper_jaw2_link.stl"/>
      </geometry>
      <material name="">
        <color rgba="1 1 0 1"/>
      </material>
    </visual>
    <collision>
      <geometry>
        <mesh filename="file:///home/omar-magdy/gp_ws/install/annin_ar4_description/share/annin_ar4_description/meshes/ar4_gripper/gripper_jaw2_link.stl"/>
      </geometry>
    </collision>
    <inertial>
      <origin xyz="-0.00423971 -0.00491236 0.00814582"/>
      <mass value="0.01"/>
      <inertia ixx="0.00000118" ixy="-0.00000004" ixz="0.00000013" iyy="0.00000110" iyz="0.00000013" izz="0.00000101"/>
    </inertial>
  </link>
  <joint name="ar4_gripper_jaw1_joint" type="prismatic">
    <origin rpy="0.0 0.0 0.0" xyz="0.0 -0.036 0"/>
    <parent link="ar4_gripper_base_link"/>
    <child link="ar4_gripper_jaw1_link"/>
    <axis xyz="-1 0 0"/>
    <limit effort="1000" lower="0.0" upper="0.014" velocity="1.0"/>
  </joint>
  <joint name="ar4_gripper_jaw2_joint" type="prismatic">
    <origin rpy="0.0 -3.141592653589793 0.0" xyz="0.0 -0.036 0"/>
    <parent link="ar4_gripper_base_link"/>
    <child link="ar4_gripper_jaw2_link"/>
    <axis xyz="-1 0 0"/>
    <limit effort="1000" lower="0" upper="0.014" velocity="1.0"/>
    <mimic joint="ar4_gripper_jaw1_joint" multiplier="1" offset="0"/>
  </joint>
  
  <!-- ***** ABB-IRB120 ROBOT .urdf SERIAL CHAIN ***** -->
  <!-- Link list: -->
  <!-- base_link -->
  <link name="base_link">
    <inertial>
      <mass value="6.215"/>
      <origin rpy="0 0 0" xyz="-0.04204 8.01E-05 0.07964"/>
      <inertia ixx="0.0247272" ixy="-8.0784E-05" ixz="0.00130902" iyy="0.0491285" iyz="-8.0419E-06" izz="0.0472376"/>
    </inertial>
    <visual>
      <origin rpy="0 0 0" xyz="0 0 0"/>
      <geometry>
        <mesh filename="file:///home/omar-magdy/gp_ws/install/ros2srrc_robots/share/ros2srrc_robots/irb120/meshes/visual/base_link.dae"/>
      </geometry>
      <material name="">
        <color rgba="0.7372549 0.3490196 0.1607843 1"/>
      </material>
    </visual>
    <collision>
      <origin rpy="0 0 0" xyz="0 0 0"/>
      <geometry>
        <mesh filename="file:///home/omar-magdy/gp_ws/install/ros2srrc_robots/share/ros2srrc_robots/irb120/meshes/collision/base_link.stl"/>
      </geometry>
      <material name="">
        <color rgba="1 1 0 1"/>
      </material>
    </collision>
  </link>
  <!-- link_1 -->
  <link name="link_1">
    <inertial>
      <mass value="3.067"/>
      <origin rpy="0 0 0" xyz="9.77E-05 -0.00012 0.23841"/>
      <inertia ixx="0.0142175" ixy="-1.28579E-05" ixz="-2.31364E-05" iyy="0.0144041" iyz="1.93404E-05" izz="0.0104533"/>
    </inertial>
    <visual>
      <origin rpy="0 0 0" xyz="0 0 0"/>
      <geometry>
        <mesh filename="file:///home/omar-magdy/gp_ws/install/ros2srrc_robots/share/ros2srrc_robots/irb120/meshes/visual/link_1.dae"/>
      </geometry>
      <material name="">
        <color rgba="0.7372549 0.3490196 0.1607843 1"/>
      </material>
    </visual>
    <collision>
      <origin rpy="0 0 0" xyz="0 0 0"/>
      <geometry>
        <mesh filename="file:///home/omar-magdy/gp_ws/install/ros2srrc_robots/share/ros2srrc_robots/irb120/meshes/collision/link_1.stl"/>
      </geometry>
      <material name="">
        <color rgba="1 1 0 1"/>
      </material>
    </collision>
  </link>
  <!-- link_2 -->
  <link name="link_2">
    <inertial>
      <mass value="3.909"/>
      <origin rpy="0 0 0" xyz="0.00078 -0.00212 0.10124"/>
      <inertia ixx="0.0603111" ixy="9.83431E-06" ixz="5.72407E-05" iyy="0.041569" iyz="-0.00050497" izz="0.0259548"/>
    </inertial>
    <visual>
      <origin rpy="0 0 0" xyz="0 0 0"/>
      <geometry>
        <mesh filename="file:///home/omar-magdy/gp_ws/install/ros2srrc_robots/share/ros2srrc_robots/irb120/meshes/visual/link_2.dae"/>
      </geometry>
      <material name="">
        <color rgba="0.7372549 0.3490196 0.1607843 1"/>
      </material>
    </visual>
    <collision>
      <origin rpy="0 0 0" xyz="0 0 0"/>
      <geometry>
        <mesh filename="file:///home/omar-magdy/gp_ws/install/ros2srrc_robots/share/ros2srrc_robots/irb120/meshes/collision/link_2.stl"/>
      </geometry>
      <material name="">
        <color rgba="1 1 0 1"/>
      </material>
    </collision>
  </link>
  <!-- link_3 -->
  <link name="link_3">
    <inertial>
      <mass value="2.944"/>
      <origin rpy="0 0 0" xyz="0.02281 0.00106 0.05791"/>
      <inertia ixx="0.00835606" ixy="-8.01545E-05" ixz="0.00142884" iyy="0.016713" iyz="-0.000182227" izz="0.0126984"/>
    </inertial>
    <visual>
      <origin rpy="0 0 0" xyz="0 0 0"/>
      <geometry>
        <mesh filename="file:///home/omar-magdy/gp_ws/install/ros2srrc_robots/share/ros2srrc_robots/irb120/meshes/visual/link_3.dae"/>
      </geometry>
      <material name="">
        <color rgba="0.7372549 0.3490196 0.1607843 1"/>
      </material>
    </visual>
    <collision>
      <origin rpy="0 0 0" xyz="0 0 0"/>
      <geometry>
        <mesh filename="file:///home/omar-magdy/gp_ws/install/ros2srrc_robots/share/ros2srrc_robots/irb120/meshes/collision/link_3.stl"/>
      </geometry>
      <material name="">
        <color rgba="1 1 0 1"/>
      </material>
    </collision>
  </link>
  <!-- link_4 -->
  <link name="link_4">
    <inertial>
      <mass value="1.328"/>
      <origin rpy="0 0 0" xyz="0.2247 0.00015 0.00041"/>
      <inertia ixx="0.00284661" ixy="-2.12765E-05" ixz="-1.6435E-05" iyy="0.00401346" iyz="1.31336E-05" izz="0.0052535"/>
    </inertial>
    <visual>
      <origin rpy="0 0 0" xyz="0 0 0"/>
      <geometry>
        <mesh filename="file:///home/omar-magdy/gp_ws/install/ros2srrc_robots/share/ros2srrc_robots/irb120/meshes/visual/link_4.dae"/>
      </geometry>
      <material name="">
        <color rgba="0.7372549 0.3490196 0.1607843 1"/>
      </material>
    </visual>
    <collision>
      <origin rpy="0 0 0" xyz="0 0 0"/>
      <geometry>
        <mesh filename="file:///home/omar-magdy/gp_ws/install/ros2srrc_robots/share/ros2srrc_robots/irb120/meshes/collision/link_4.stl"/>
      </geometry>
      <material name="">
        <color rgba="1 1 0 1"/>
      </material>
    </collision>
  </link>
  <!-- link_5 -->
  <link name="link_5">
    <inertial>
      <mass value="0.546"/>
      <origin rpy="0 0 0" xyz="-0.00109 3.68E-05 6.22E-05"/>
      <inertia ixx="0.000404891" ixy="1.61943E-06" ixz="8.46805E-07" iyy="0.000892825" iyz="-1.51792E-08" izz="0.000815468"/>
    </inertial>
    <visual>
      <origin rpy="0 0 0" xyz="0 0 0"/>
      <geometry>
        <mesh filename="file:///home/omar-magdy/gp_ws/install/ros2srrc_robots/share/ros2srrc_robots/irb120/meshes/visual/link_5.dae"/>
      </geometry>
      <material name="">
        <color rgba="0.7372549 0.3490196 0.1607843 1"/>
      </material>
    </visual>
    <collision>
      <origin rpy="0 0 0" xyz="0 0 0"/>
      <geometry>
        <mesh filename="file:///home/omar-magdy/gp_ws/install/ros2srrc_robots/share/ros2srrc_robots/irb120/meshes/collision/link_5.stl"/>
      </geometry>
      <material name="">
        <color rgba="1 1 0 1"/>
      </material>
    </collision>
  </link>
  <!-- link_6 -->
  <link name="link_6">
    <inertial>
      <mass value="0.137"/>
      <origin rpy="0 0 0" xyz="-0.00706 -0.00017 -1.32E-06"/>
      <inertia ixx="0.001" ixy="0" ixz="0" iyy="0.001" iyz="0" izz="0.001"/>
    </inertial>
    <visual>
      <origin rpy="0 0 0" xyz="0 0 0"/>
      <geometry>
        <mesh filename="file:///home/omar-magdy/gp_ws/install/ros2srrc_robots/share/ros2srrc_robots/irb120/meshes/visual/link_6.dae"/>
      </geometry>
      <material name="">
        <color rgba="0.1882353 0.1960784 0.2039216 1"/>
      </material>
    </visual>
    <collision>
      <origin rpy="0 0 0" xyz="0 0 0"/>
      <geometry>
        <mesh filename="file:///home/omar-magdy/gp_ws/install/ros2srrc_robots/share/ros2srrc_robots/irb120/meshes/collision/link_6.stl"/>
      </geometry>
      <material name="">
        <color rgba="1 1 0 1"/>
      </material>
    </collision>
  </link>
  <!-- end of link list -->
  <!-- Joint list: -->
  <!-- joint_1 -->
  <joint name="joint_1" type="revolute">
    <origin rpy="0 0 0" xyz="0 0 0"/>
    <parent link="base_link"/>
    <child link="link_1"/>
    <limit effort="1000" lower="-2.87979" upper="2.87979" velocity="4.36332"/>
    <axis xyz="0 0 1"/>
    <dynamics damping="50.0" friction="1.0"/>
  </joint>
  <!-- joint_2 -->
  <joint name="joint_2" type="revolute">
    <origin rpy="0 0 0" xyz="0 0 0.29"/>
    <parent link="link_1"/>
    <child link="link_2"/>
    <limit effort="1000" lower="-1.91986" upper="1.91986" velocity="4.36332"/>
    <axis xyz="0 1 0"/>
    <dynamics damping="50.0" friction="1.0"/>
  </joint>
  <!-- joint_3 -->
  <joint name="joint_3" type="revolute">
    <origin rpy="0 0 0" xyz="0 0 0.27"/>
    <parent link="link_2"/>
    <child link="link_3"/>
    <limit effort="1000" lower="-1.91986" upper="1.22173" velocity="4.36332"/>
    <axis xyz="0 1 0"/>
    <dynamics damping="10.0" friction="1.0"/>
  </joint>
  <!-- joint_4 -->
  <joint name="joint_4" type="revolute">
    <origin rpy="0 0 0" xyz="0 0 0.07"/>
    <parent link="link_3"/>
    <child link="link_4"/>
    <limit effort="1000" lower="-2.79253" upper="2.79253" velocity="5.58505"/>
    <axis xyz="1 0 0"/>
    <dynamics damping="5.0" friction="1.0"/>
  </joint>
  <!-- joint_5 -->
  <joint name="joint_5" type="revolute">
    <origin rpy="0 0 0" xyz="0.302 0 0"/>
    <parent link="link_4"/>
    <child link="link_5"/>
    <limit effort="1000" lower="-2.094395" upper="2.094395" velocity="5.58505"/>
    <axis xyz="0 1 0"/>
    <dynamics damping="2.0" friction="1.0"/>
  </joint>
  <!-- joint_6 -->
  <joint name="joint_6" type="revolute">
    <origin rpy="0 0 0" xyz="0.072 0 0"/>
    <parent link="link_5"/>
    <child link="link_6"/>
    <limit effort="1000" lower="-6.98132" upper="6.98132" velocity="7.33038"/>
    <axis xyz="1 0 0"/>
    <dynamics damping="1.0" friction="1.0"/>
  </joint>
  <!-- end of joint list -->
  <!-- ROS-Industrial 'base' frame: base_link to ABB World Coordinates transform -->
  <link name="base"/>
  <joint name="base_link-base" type="fixed">
    <origin rpy="0 0 0" xyz="0 0 0"/>
    <parent link="base_link"/>
    <child link="base"/>
  </joint>
  <!-- ROS-Industrial 'flange' frame: attachment point for EEF models -->
  <link name="flange"/>
  <joint name="joint_6-flange" type="fixed">
    <origin rpy="0 0 0" xyz="0 0 0"/>
    <parent link="link_6"/>
    <child link="flange"/>
  </joint>
  <!-- ROS-Industrial 'tool0' frame: all-zeros tool frame -->
  <link name="tool0"/>
  <joint name="link_6-tool0" type="fixed">
    <origin rpy="0 1.5707963267948966 0" xyz="0 0 0"/>
    <parent link="flange"/>
    <child link="tool0"/>
  </joint>
  <!-- IRB120 Fixed Joint to World with offset -->
  <joint name="irb120_world_joint" type="fixed">
    <parent link="world"/>
    <child link="base_link"/>
    <origin rpy="0 0 0" xyz="-1.2 0 0"/>
  </joint>
  
  
  
  <!-- 3. Load ROS2_CONTROL: -->
  <gazebo>
  <plugin filename="gz_ros2_control-system" name="gz_ros2_control::GazeboSimROS2ControlPlugin">
    <parameters>/home/omar-magdy/gp_ws/install/dual_arms/share/dual_arms/config/dual_arms_controller.yaml</parameters>
  </plugin>
</gazebo>
  <ros2_control name="GazeboSimSystem" type="system">
    <hardware>
      <plugin>gz_ros2_control/GazeboSimSystem</plugin>
    </hardware>
    <!-- AR4 Joints -->
  <joint name="ar4_joint_1">
    <command_interface name="position">
      <param name="min">-2.9670597283903604</param>
      <param name="max">2.9670597283903604</param>
    </command_interface>
    <state_interface name="position">
		<param name="initial_value">0.0</param>
	</state_interface>
	<state_interface name="velocity"/>
  </joint>
  <joint name="ar4_joint_2">
    <command_interface name="position">
      <param name="min">-0.7330382858376184</param>
      <param name="max">1.5707963267948966</param>
    </command_interface>
    <state_interface name="position">
		<param name="initial_value">0.0</param>
	</state_interface>
	<state_interface name="velocity"/>
  </joint>
    <joint name="ar4_joint_3">
    <command_interface name="position">
      <param name="min">-1.5533430342749532</param>
      <param name="max">0.9075712110370514</param>
    </command_interface>
    <state_interface name="position">
		<param name="initial_value">0.0</param>
	</state_interface>
	<state_interface name="velocity"/>
  </joint>
    <joint name="ar4_joint_4">
    <command_interface name="position">
      <param name="min">-3.141592653589793</param>
      <param name="max">3.141592653589793</param>
    </command_interface>
   <state_interface name="position">
        <param name="initial_value">0.0</param>
      </state_interface>
      <state_interface name="velocity"/>
  </joint>
    <joint name="ar4_joint_5">
    <command_interface name="position">
      <param name="min">-1.8325957145940461</param>
      <param name="max">1.8325957145940461</param>
    </command_interface>
    <state_interface name="position">
        <param name="initial_value">0.0</param>
      </state_interface>
      <state_interface name="velocity"/>
  </joint>
    <joint name="ar4_joint_6">
    <command_interface name="position">
      <param name="min">-3.141592653589793</param>
      <param name="max">3.141592653589793</param>
    </command_interface>
    <state_interface name="position">
        <param name="initial_value">0.0</param>
      </state_interface>
      <state_interface name="velocity"/>
  </joint>
  <!-- Add ar4_joint_3 to ar4_joint_6 similarly, matching URDF limits -->
  <!-- Gripper Joint -->
  <joint name="ar4_gripper_jaw1_joint">
    <command_interface name="position">
      <param name="min">0.0</param>
      <param name="max">0.014</param>
    </command_interface>
    <command_interface name="velocity">
      <param name="min">-1.0</param>
      <param name="max">1.0</param>
    </command_interface>
    <state_interface name="position"/>
    <state_interface name="velocity"/>
  </joint>
    <!-- irb120_joint1 -->
    <joint name="joint_1">
      <command_interface name="position">
        <param name="min">-2.87979</param>
        <param name="max">2.87979</param>
      </command_interface>
      <command_interface name="velocity">
        <param name="min">-4.36332</param>
        <param name="max">4.36332</param>
      </command_interface>
      <state_interface name="position">
        <param name="initial_value">0.0</param>
      </state_interface>
      <state_interface name="velocity"/>
    </joint>
    <!-- irb120_joint2 -->
    <joint name="joint_2">
      <command_interface name="position">
        <param name="min">-1.91986</param>
        <param name="max">1.91986</param>
      </command_interface>
      <command_interface name="velocity">
        <param name="min">-4.36332</param>
        <param name="max">4.36332</param>
      </command_interface>
      <state_interface name="position">
        <param name="initial_value">0.0</param>
      </state_interface>
      <state_interface name="velocity"/>
    </joint>
    <!-- irb120_joint3 -->
    <joint name="joint_3">
      <command_interface name="position">
        <param name="min">-1.91986</param>
        <param name="max">1.22173</param>
      </command_interface>
      <command_interface name="velocity">
        <param name="min">-4.36332</param>
        <param name="max">4.36332</param>
      </command_interface>
      <state_interface name="position">
        <param name="initial_value">0.0</param>
      </state_interface>
      <state_interface name="velocity"/>
    </joint>
    <!-- irb120_joint4 -->
    <joint name="joint_4">
      <command_interface name="position">
        <param name="min">-2.79253</param>
        <param name="max">2.79253</param>
      </command_interface>
      <command_interface name="velocity">
        <param name="min">-5.58505</param>
        <param name="max">5.58505</param>
      </command_interface>
      <state_interface name="position">
        <param name="initial_value">0.0</param>
      </state_interface>
      <state_interface name="velocity"/>
    </joint>
    <!-- irb120_joint5 -->
    <joint name="joint_5">
      <command_interface name="position">
        <param name="min">-2.00</param>
        <!-- Joint5 limits lowered to +-2rad -->
        <param name="max">2.00</param>
      </command_interface>
      <command_interface name="velocity">
        <param name="min">-5.58505</param>
        <param name="max">5.58505</param>
      </command_interface>
      <state_interface name="position">
        <param name="initial_value">1.570796</param>
      </state_interface>
      <state_interface name="velocity"/>
    </joint>
    <!-- irb120_joint6 -->
    <joint name="joint_6">
      <command_interface name="position">
        <param name="min">-6.98132</param>
        <param name="max">6.98132</param>
      </command_interface>
      <command_interface name="velocity">
        <param name="min">-7.33038</param>
        <param name="max">7.33038</param>
      </command_interface>
      <state_interface name="position">
        <param name="initial_value">0.0</param>
      </state_interface>
      <state_interface name="velocity"/>
    </joint>
  </ros2_control>
  
</robot>
